Fallback Test Execution Report
=============================

Timestamp: 2025-07-16 08:43:43
Exit Code: 2
Success: False
Command: /Users/4d/Documents/GitHub/GeneralizedNotationNotation/.venv/bin/python -m pytest --verbose --tb=short --junitxml=../output/test_reports/pytest_report.xml --maxfail=20 --durations=15 --disable-warnings --strict-markers -c/Users/4d/Documents/GitHub/GeneralizedNotationNotation/pytest.ini --cov=src --cov-report=html:../output/test_reports/coverage --cov-report=json:../output/test_reports/test_coverage.json --cov-report=term-missing --cov-fail-under=0 -m not slow /Users/4d/Documents/GitHub/GeneralizedNotationNotation/src/tests

STDOUT:
============================= test session starts ==============================
platform darwin -- Python 3.13.5, pytest-8.4.1, pluggy-1.6.0 -- /Users/4d/Documents/GitHub/GeneralizedNotationNotation/.venv/bin/python
cachedir: .pytest_cache
rootdir: /Users/4d/Documents/GitHub/GeneralizedNotationNotation
configfile: pytest.ini
plugins: anyio-4.9.0, cov-6.2.1, mock-3.14.1
collecting ... collected 404 items / 1 error / 10 deselected / 394 selected

==================================== ERRORS ====================================
__________________ ERROR collecting src/tests/test_render.py ___________________
'render' not found in `markers` configuration option
- generated xml file: /Users/4d/Documents/GitHub/output/test_reports/pytest_report.xml -
=========================== short test summary info ============================
ERROR src/tests/test_render.py - Failed: 'render' not found in `markers` conf...
!!!!!!!!!!!!!!!!!!!! Interrupted: 1 error during collection !!!!!!!!!!!!!!!!!!!!
======================= 10 deselected, 1 error in 3.00s ========================


STDERR:
